


 pi@raspberrypi:~/PySyft/examples/tutorials/advanced/websockets-example-MNIST $ python run_websocket_server.py --id alice --port 8777
/home/pi/federated_learning/lib/python3.7/site-packages/tensorflow_core/python/framework/dtypes.py:516: FutureWarning: Passing (type, 1) or '1type' as a synonym of type is deprecated; in a future version of numpy, it will be understood as (type, (1,)) / '(1,)type'.
  _np_qint8 = np.dtype([("qint8", np.int8, 1)])
/home/pi/federated_learning/lib/python3.7/site-packages/tensorflow_core/python/framework/dtypes.py:517: FutureWarning: Passing (type, 1) or '1type' as a synonym of type is deprecated; in a future version of numpy, it will be understood as (type, (1,)) / '(1,)type'.
  _np_quint8 = np.dtype([("quint8", np.uint8, 1)])
/home/pi/federated_learning/lib/python3.7/site-packages/tensorflow_core/python/framework/dtypes.py:518: FutureWarning: Passing (type, 1) or '1type' as a synonym of type is deprecated; in a future version of numpy, it will be understood as (type, (1,)) / '(1,)type'.
  _np_qint16 = np.dtype([("qint16", np.int16, 1)])
/home/pi/federated_learning/lib/python3.7/site-packages/tensorflow_core/python/framework/dtypes.py:519: FutureWarning: Passing (type, 1) or '1type' as a synonym of type is deprecated; in a future version of numpy, it will be understood as (type, (1,)) / '(1,)type'.
  _np_quint16 = np.dtype([("quint16", np.uint16, 1)])
/home/pi/federated_learning/lib/python3.7/site-packages/tensorflow_core/python/framework/dtypes.py:520: FutureWarning: Passing (type, 1) or '1type' as a synonym of type is deprecated; in a future version of numpy, it will be understood as (type, (1,)) / '(1,)type'.
  _np_qint32 = np.dtype([("qint32", np.int32, 1)])
/home/pi/federated_learning/lib/python3.7/site-packages/tensorflow_core/python/framework/dtypes.py:525: FutureWarning: Passing (type, 1) or '1type' as a synonym of type is deprecated; in a future version of numpy, it will be understood as (type, (1,)) / '(1,)type'.
  np_resource = np.dtype([("resource", np.ubyte, 1)])
/home/pi/federated_learning/lib/python3.7/site-packages/tensorboard/compat/tensorflow_stub/dtypes.py:541: FutureWarning: Passing (type, 1) or '1type' as a synonym of type is deprecated; in a future version of numpy, it will be understood as (type, (1,)) / '(1,)type'.
  _np_qint8 = np.dtype([("qint8", np.int8, 1)])
/home/pi/federated_learning/lib/python3.7/site-packages/tensorboard/compat/tensorflow_stub/dtypes.py:542: FutureWarning: Passing (type, 1) or '1type' as a synonym of type is deprecated; in a future version of numpy, it will be understood as (type, (1,)) / '(1,)type'.
  _np_quint8 = np.dtype([("quint8", np.uint8, 1)])
/home/pi/federated_learning/lib/python3.7/site-packages/tensorboard/compat/tensorflow_stub/dtypes.py:543: FutureWarning: Passing (type, 1) or '1type' as a synonym of type is deprecated; in a future version of numpy, it will be understood as (type, (1,)) / '(1,)type'.
  _np_qint16 = np.dtype([("qint16", np.int16, 1)])
/home/pi/federated_learning/lib/python3.7/site-packages/tensorboard/compat/tensorflow_stub/dtypes.py:544: FutureWarning: Passing (type, 1) or '1type' as a synonym of type is deprecated; in a future version of numpy, it will be understood as (type, (1,)) / '(1,)type'.
  _np_quint16 = np.dtype([("quint16", np.uint16, 1)])
/home/pi/federated_learning/lib/python3.7/site-packages/tensorboard/compat/tensorflow_stub/dtypes.py:545: FutureWarning: Passing (type, 1) or '1type' as a synonym of type is deprecated; in a future version of numpy, it will be understood as (type, (1,)) / '(1,)type'.
  _np_qint32 = np.dtype([("qint32", np.int32, 1)])
/home/pi/federated_learning/lib/python3.7/site-packages/tensorboard/compat/tensorflow_stub/dtypes.py:550: FutureWarning: Passing (type, 1) or '1type' as a synonym of type is deprecated; in a future version of numpy, it will be understood as (type, (1,)) / '(1,)type'.
  np_resource = np.dtype([("resource", np.ubyte, 1)])
WARNING: Logging before flag parsing goes to stderr.
W0818 22:47:37.177268 1996446416 deprecation_wrapper.py:118] From /home/pi/federated_learning/lib/python3.7/site-packages/tensorflow/__init__.py:98: The name tf.AUTO_REUSE is deprecated. Please use tf.compat.v1.AUTO_REUSE instead.

W0818 22:47:37.178248 1996446416 deprecation_wrapper.py:118] From /home/pi/federated_learning/lib/python3.7/site-packages/tensorflow/__init__.py:98: The name tf.AttrValue is deprecated. Please use tf.compat.v1.AttrValue instead.

W0818 22:47:37.178804 1996446416 deprecation_wrapper.py:118] From /home/pi/federated_learning/lib/python3.7/site-packages/tensorflow/__init__.py:98: The name tf.COMPILER_VERSION is deprecated. Please use tf.version.COMPILER_VERSION instead.

W0818 22:47:37.179308 1996446416 deprecation_wrapper.py:118] From /home/pi/federated_learning/lib/python3.7/site-packages/tensorflow/__init__.py:98: The name tf.CXX11_ABI_FLAG is deprecated. Please use tf.sysconfig.CXX11_ABI_FLAG instead.

W0818 22:47:37.179820 1996446416 deprecation_wrapper.py:118] From /home/pi/federated_learning/lib/python3.7/site-packages/tensorflow/__init__.py:98: The name tf.ConditionalAccumulator is deprecated. Please use tf.compat.v1.ConditionalAccumulator instead.

W0818 22:47:37.206732 1996446416 secure_random.py:26] Falling back to insecure randomness since the required custom op could not be found for the installed version of TensorFlow. Fix this by compiling custom ops. Missing file was '/home/pi/federated_learning/lib/python3.7/site-packages/tf_encrypted/operations/secure_random/secure_random_module_tf_1.13.1.so'
Serving. Press CTRL-C to stop.
E0818 22:48:56.926912 1996446416 base_events.py:1608] Task exception was never retrieved
future: <Task finished coro=<WebsocketServerWorker._producer_handler() done, defined at /home/pi/federated_learning/lib/python3.7/site-packages/syft/workers/websocket_server.py:91> exception=ValueError('not enough values to unpack (expected 8, got 2)')>
Traceback (most recent call last):
  File "/home/pi/federated_learning/lib/python3.7/site-packages/syft/workers/websocket_server.py", line 109, in _producer_handler
    response = self._recv_msg(message)
  File "/home/pi/federated_learning/lib/python3.7/site-packages/syft/workers/websocket_server.py", line 120, in _recv_msg
    return self.recv_msg(message)
  File "/home/pi/federated_learning/lib/python3.7/site-packages/syft/workers/base.py", line 256, in recv_msg
    msg = sy.serde.deserialize(bin_message, worker=self)
  File "/home/pi/federated_learning/lib/python3.7/site-packages/syft/serde/serde.py", line 275, in deserialize
    return _detail(worker, simple_objects)
  File "/home/pi/federated_learning/lib/python3.7/site-packages/syft/serde/serde.py", line 438, in _detail
    return detailers[obj[0]](worker, obj[1])
  File "/home/pi/federated_learning/lib/python3.7/site-packages/syft/frameworks/torch/tensors/interpreters/autograd.py", line 314, in detail
    tensor_tuple
ValueError: not enough values to unpack (expected 8, got 2)
E0818 22:48:57.556528 1996446416 base_events.py:1608] Task exception was never retrieved
future: <Task finished coro=<WebsocketServerWorker._producer_handler() done, defined at /home/pi/federated_learning/lib/python3.7/site-packages/syft/workers/websocket_server.py:91> exception=ValueError('not enough values to unpack (expected 8, got 2)')>
Traceback (most recent call last):
  File "/home/pi/federated_learning/lib/python3.7/site-packages/syft/workers/websocket_server.py", line 109, in _producer_handler
    response = self._recv_msg(message)
  File "/home/pi/federated_learning/lib/python3.7/site-packages/syft/workers/websocket_server.py", line 120, in _recv_msg
    return self.recv_msg(message)
  File "/home/pi/federated_learning/lib/python3.7/site-packages/syft/workers/base.py", line 256, in recv_msg
    msg = sy.serde.deserialize(bin_message, worker=self)
  File "/home/pi/federated_learning/lib/python3.7/site-packages/syft/serde/serde.py", line 275, in deserialize
    return _detail(worker, simple_objects)
  File "/home/pi/federated_learning/lib/python3.7/site-packages/syft/serde/serde.py", line 438, in _detail
    return detailers[obj[0]](worker, obj[1])
  File "/home/pi/federated_learning/lib/python3.7/site-packages/syft/frameworks/torch/tensors/interpreters/autograd.py", line 314, in detail
    tensor_tuple
ValueError: not enough values to unpack (expected 8, got 2)



/////////////////////////////////////////////////////////////////////////////////////////////



E0818 22:50:10.221624 1995979472 base_events.py:1608] Future exception was never retrieved
future: <Future finished exception=ConnectionClosedError('code = 1006 (connection closed abnormally [internal]), no reason')>
Traceback (most recent call last):
  File "/home/pi/federated_learning/lib/python3.7/site-packages/websockets/protocol.py", line 795, in transfer_data
    message = await self.read_message()
  File "/home/pi/federated_learning/lib/python3.7/site-packages/websockets/protocol.py", line 863, in read_message
    frame = await self.read_data_frame(max_size=self.max_size)
  File "/home/pi/federated_learning/lib/python3.7/site-packages/websockets/protocol.py", line 938, in read_data_frame
    frame = await self.read_frame(max_size)
  File "/home/pi/federated_learning/lib/python3.7/site-packages/websockets/protocol.py", line 1018, in read_frame
    extensions=self.extensions,
  File "/home/pi/federated_learning/lib/python3.7/site-packages/websockets/framing.py", line 121, in read
    data = await reader(2)
  File "/usr/lib/python3.7/asyncio/streams.py", line 679, in readexactly
    await self._wait_for_data('readexactly')
  File "/usr/lib/python3.7/asyncio/streams.py", line 473, in _wait_for_data
    await self._waiter
concurrent.futures._base.CancelledError

The above exception was the direct cause of the following exception:

websockets.exceptions.ConnectionClosedError: code = 1006 (connection closed abnormally [internal]), no reason
E0818 22:50:10.239052 1995979472 base_events.py:1608] Future exception was never retrieved
future: <Future finished exception=ConnectionClosedError('code = 1006 (connection closed abnormally [internal]), no reason')>
Traceback (most recent call last):
  File "/home/pi/federated_learning/lib/python3.7/site-packages/websockets/protocol.py", line 795, in transfer_data
    message = await self.read_message()
  File "/home/pi/federated_learning/lib/python3.7/site-packages/websockets/protocol.py", line 863, in read_message
    frame = await self.read_data_frame(max_size=self.max_size)
  File "/home/pi/federated_learning/lib/python3.7/site-packages/websockets/protocol.py", line 938, in read_data_frame
    frame = await self.read_frame(max_size)
  File "/home/pi/federated_learning/lib/python3.7/site-packages/websockets/protocol.py", line 1018, in read_frame
    extensions=self.extensions,
  File "/home/pi/federated_learning/lib/python3.7/site-packages/websockets/framing.py", line 121, in read
    data = await reader(2)
  File "/usr/lib/python3.7/asyncio/streams.py", line 679, in readexactly
    await self._wait_for_data('readexactly')
  File "/usr/lib/python3.7/asyncio/streams.py", line 473, in _wait_for_data
    await self._waiter
concurrent.futures._base.CancelledError

The above exception was the direct cause of the following exception:

websockets.exceptions.ConnectionClosedError: code = 1006 (connection closed abnormally [internal]), no reason
E0818 22:50:10.242452 1995979472 base_events.py:1608] Future exception was never retrieved
future: <Future finished exception=ConnectionClosedError('code = 1006 (connection closed abnormally [internal]), no reason')>
Traceback (most recent call last):
  File "/home/pi/federated_learning/lib/python3.7/site-packages/websockets/protocol.py", line 795, in transfer_data
    message = await self.read_message()
  File "/home/pi/federated_learning/lib/python3.7/site-packages/websockets/protocol.py", line 863, in read_message
    frame = await self.read_data_frame(max_size=self.max_size)
  File "/home/pi/federated_learning/lib/python3.7/site-packages/websockets/protocol.py", line 938, in read_data_frame
    frame = await self.read_frame(max_size)
  File "/home/pi/federated_learning/lib/python3.7/site-packages/websockets/protocol.py", line 1018, in read_frame
    extensions=self.extensions,
  File "/home/pi/federated_learning/lib/python3.7/site-packages/websockets/framing.py", line 121, in read
    data = await reader(2)
  File "/usr/lib/python3.7/asyncio/streams.py", line 679, in readexactly
    await self._wait_for_data('readexactly')
  File "/usr/lib/python3.7/asyncio/streams.py", line 473, in _wait_for_data
    await self._waiter
concurrent.futures._base.CancelledError

The above exception was the direct cause of the following exception:

websockets.exceptions.ConnectionClosedError: code = 1006 (connection closed abnormally [internal]), no reason